<?xml version="1.0" encoding="UTF-8"?>
<testsuite errors="0" failures="4" name="BalancerOnlyTest.BalancerInitTest-20151020170640" tests="4" time="10.271">
	<properties/>
	<system-out>
<![CDATA[2236
]]>	</system-out>
	<system-err>
<![CDATA[]]>	</system-err>
	<testcase classname="BalancerOnlyTest.BalancerInitTest" name="testBalance" time="2.471">
		<failure message="" type="AssertionError">
<![CDATA[Traceback (most recent call last):
  File "/home/saikappa/workspace/SciPass/python/t/BalancerOnlyTest.py", line 275, in testBalance
    self.assertTrue( len(flows) == 1132)
AssertionError
]]>		</failure>
	</testcase>
	<testcase classname="BalancerOnlyTest.BalancerInitTest" name="testInit" time="2.513">
		<failure message="" type="AssertionError">
<![CDATA[Traceback (most recent call last):
  File "/home/saikappa/workspace/SciPass/python/t/BalancerOnlyTest.py", line 173, in testInit
    self.assertTrue( len(flows) == 1132)
AssertionError
]]>		</failure>
	</testcase>
	<testcase classname="BalancerOnlyTest.BalancerInitTest" name="test_bad_flow" time="2.524">
		<failure message="" type="AssertionError">
<![CDATA[Traceback (most recent call last):
  File "/home/saikappa/workspace/SciPass/python/t/BalancerOnlyTest.py", line 41, in test_bad_flow
    self.assertTrue( len(flows) == 1132)
AssertionError

Stdout:
2236
]]>		</failure>
	</testcase>
	<testcase classname="BalancerOnlyTest.BalancerInitTest" name="test_good_flow" time="2.763">
		<failure message="" type="AssertionError">
<![CDATA[Traceback (most recent call last):
  File "/home/saikappa/workspace/SciPass/python/t/BalancerOnlyTest.py", line 107, in test_good_flow
    self.assertTrue( len(flows) == 1132)
AssertionError
]]>		</failure>
	</testcase>
</testsuite>
